[2024-02-26T16:25:41.490+0700] {taskinstance.py:1956} INFO - Dependencies all met for dep_context=non-requeueable deps ti=<TaskInstance: missed_deadline_job_dag.create_missed_deadline_table manual__2024-02-26T09:25:40.972548+00:00 [queued]>
[2024-02-26T16:25:41.497+0700] {taskinstance.py:1956} INFO - Dependencies all met for dep_context=requeueable deps ti=<TaskInstance: missed_deadline_job_dag.create_missed_deadline_table manual__2024-02-26T09:25:40.972548+00:00 [queued]>
[2024-02-26T16:25:41.497+0700] {taskinstance.py:2170} INFO - Starting attempt 1 of 1
[2024-02-26T16:25:41.508+0700] {taskinstance.py:2191} INFO - Executing <Task(PostgresOperator): create_missed_deadline_table> on 2024-02-26 09:25:40.972548+00:00
[2024-02-26T16:25:41.509+0700] {standard_task_runner.py:60} INFO - Started process 25129 to run task
[2024-02-26T16:25:41.512+0700] {standard_task_runner.py:87} INFO - Running: ['***', 'tasks', 'run', 'missed_deadline_job_dag', 'create_missed_deadline_table', 'manual__2024-02-26T09:25:40.972548+00:00', '--job-id', '49', '--raw', '--subdir', 'DAGS_FOLDER/missed_deadlinee_dag.py', '--cfg-path', '/tmp/tmpka5qs9zf']
[2024-02-26T16:25:41.513+0700] {standard_task_runner.py:88} INFO - Job 49: Subtask create_missed_deadline_table
[2024-02-26T16:25:41.566+0700] {task_command.py:423} INFO - Running <TaskInstance: missed_deadline_job_dag.create_missed_deadline_table manual__2024-02-26T09:25:40.972548+00:00 [running]> on host MinhNhut.
[2024-02-26T16:25:41.642+0700] {taskinstance.py:2480} INFO - Exporting env vars: AIRFLOW_CTX_DAG_OWNER='***' AIRFLOW_CTX_DAG_ID='missed_deadline_job_dag' AIRFLOW_CTX_TASK_ID='create_missed_deadline_table' AIRFLOW_CTX_EXECUTION_DATE='2024-02-26T09:25:40.972548+00:00' AIRFLOW_CTX_TRY_NUMBER='1' AIRFLOW_CTX_DAG_RUN_ID='manual__2024-02-26T09:25:40.972548+00:00'
[2024-02-26T16:25:41.643+0700] {sql.py:276} INFO - Executing: CREATE TABLE IF NOT EXISTS olist_missed_deadline_tb(
    id SERIAL,
    order_id VARCHAR(200),
    seller_id VARCHAR(200),
    shipping_limit_date DATETIME,
    price FLOAT,
    freight_value, FLOAT,
    product_id VARCHAR(200),
    product_category_name VARCHAR(200),
    customer_id VARCHAR(200),
    order_status VARCHAR(200),
    order_purchase_timestamp DATETIME,
    order_delivered_carrier_date DATETIME,
    order_delivered_customer_date DATETIME,
    order_estimated_delivery_date DATETIME,
    PRIMARY KEY (id, order_id, seller_id, product_id)
);
[2024-02-26T16:25:41.657+0700] {base.py:83} INFO - Using connection ID 'olist_pg_conn' for task execution.
[2024-02-26T16:25:41.674+0700] {base.py:83} INFO - Using connection ID 'olist_pg_conn' for task execution.
[2024-02-26T16:25:41.684+0700] {taskinstance.py:2698} ERROR - Task failed with exception
Traceback (most recent call last):
  File "/home/nhut/etl-airflow/.venv/lib/python3.10/site-packages/airflow/models/taskinstance.py", line 433, in _execute_task
    result = execute_callable(context=context, **execute_callable_kwargs)
  File "/home/nhut/etl-airflow/.venv/lib/python3.10/site-packages/airflow/providers/common/sql/operators/sql.py", line 282, in execute
    output = hook.run(
  File "/home/nhut/etl-airflow/.venv/lib/python3.10/site-packages/airflow/providers/common/sql/hooks/sql.py", line 391, in run
    with closing(self.get_conn()) as conn:
  File "/home/nhut/etl-airflow/.venv/lib/python3.10/site-packages/airflow/providers/postgres/hooks/postgres.py", line 158, in get_conn
    self.conn = psycopg2.connect(**conn_args)
  File "/home/nhut/etl-airflow/.venv/lib/python3.10/site-packages/psycopg2/__init__.py", line 122, in connect
    conn = _connect(dsn, connection_factory=connection_factory, **kwasync)
psycopg2.OperationalError: connection to server at "localhost" (127.0.0.1), port 5432 failed: FATAL:  database "olist_warehouse_db" does not exist

[2024-02-26T16:25:41.697+0700] {taskinstance.py:1138} INFO - Marking task as FAILED. dag_id=missed_deadline_job_dag, task_id=create_missed_deadline_table, execution_date=20240226T092540, start_date=20240226T092541, end_date=20240226T092541
[2024-02-26T16:25:41.706+0700] {standard_task_runner.py:107} ERROR - Failed to execute job 49 for task create_missed_deadline_table (connection to server at "localhost" (127.0.0.1), port 5432 failed: FATAL:  database "olist_warehouse_db" does not exist
; 25129)
[2024-02-26T16:25:41.724+0700] {local_task_job_runner.py:234} INFO - Task exited with return code 1
[2024-02-26T16:25:41.746+0700] {taskinstance.py:3280} INFO - 0 downstream tasks scheduled from follow-on schedule check
